<?xml version="1.0" ?>
<!-- =================================================================================== -->
<!-- |    This document was autogenerated by xacro from src/ur5_description/urdf/robot/ur5_wsg50.urdf.xacro | -->
<!-- |    EDITING THIS FILE BY HAND IS NOT RECOMMENDED                                 | -->
<!-- =================================================================================== -->
<robot name="UR5" xmlns:controller="http://playerstage.sourceforge.net/gazebo/xmlschema/#controller" xmlns:interface="http://playerstage.sourceforge.net/gazebo/xmlschema/#interface" xmlns:sensor="http://playerstage.sourceforge.net/gazebo/xmlschema/#sensor">
  <!-- <xacro:macro name="sensor_r430_gazebo"> -->
  <!-- gazebo reference="${prefix}_rgb_base_link" -->
  <!-- <gazebo reference="${prefix}_camera_link">
      <sensor type="depth" name="${prefix}_depth_sensor">
        <always_on>true</always_on>
        <update_rate>15.0</update_rate>
        <camera>
          <horizontal_fov>${91.2*M_PI/180.0}</horizontal_fov>
          <image>
            <format>R8G8B8</format>
            <width>640</width>
            <height>480</height>
          </image>
          <clip>
            <near>0.3</near>
            <far>10.0</far>
          </clip>
        </camera>
        <plugin name="${prefix}_controller" filename="libgazebo_ros_openni_kinect.so">
          <cameraName>${prefix_topic}</cameraName>
          <alwaysOn>true</alwaysOn>
          <updateRate>10</updateRate>
          <imageTopicName>rgb/image_raw</imageTopicName>
          <depthImageTopicName>depth/image_raw</depthImageTopicName>
          <pointCloudTopicName>depth/points</pointCloudTopicName>
          <cameraInfoTopicName>rgb/camera_info</cameraInfoTopicName>
          <depthImageCameraInfoTopicName>depth/camera_info</depthImageCameraInfoTopicName>
          <frameName>/${prefix}_camera_depth_optical_frame</frameName>
          <baseline>0.1</baseline>
          <distortion_k1>0.0</distortion_k1>
          <distortion_k2>0.0</distortion_k2>
          <distortion_k3>0.0</distortion_k3>
          <distortion_t1>0.0</distortion_t1>
          <distortion_t2>0.0</distortion_t2>
          <pointCloudCutoff>0.4</pointCloudCutoff>
        </plugin>
      </sensor>
    </gazebo>
  </xacro:macro> -->
  <!-- measured from model -->
  <link name="robot_arm_base_link">
    <visual>
      <origin rpy="0 0 3.141592653589793" xyz="0 0 0"/>
      <geometry>
        <mesh filename="package://ur5_description/meshes/ur5/visual/base.dae"/>
      </geometry>
      <material name="LightGrey">
        <color rgba="0.7 0.7 0.7 1.0"/>
      </material>
    </visual>
    <collision>
      <origin rpy="0 0 3.141592653589793" xyz="0 0 0"/>
      <geometry>
        <mesh filename="package://ur5_description/meshes/ur5/collision/base.stl"/>
      </geometry>
    </collision>
    <inertial>
      <mass value="4.0"/>
      <origin rpy="0 0 0" xyz="0.0 0.0 0.0"/>
      <inertia ixx="0.00443333156" ixy="0.0" ixz="0.0" iyy="0.00443333156" iyz="0.0" izz="0.0072"/>
    </inertial>
  </link>
  <joint name="robot_arm_shoulder_pan_joint" type="revolute">
    <parent link="robot_arm_base_link"/>
    <child link="robot_arm_shoulder_link"/>
    <origin rpy="0 0 3.1416082855660026" xyz="0 0 0.08892521634598444"/>
    <axis xyz="0 0 1"/>
    <limit effort="150.0" lower="-3.141592653589793" upper="3.141592653589793" velocity="3.15"/>
    <dynamics damping="0.0" friction="0.0"/>
  </joint>
  <link name="robot_arm_shoulder_link">
    <visual>
      <origin rpy="0 0 3.141592653589793" xyz="0 0 0"/>
      <geometry>
        <mesh filename="package://ur5_description/meshes/ur5/visual/shoulder.dae"/>
      </geometry>
      <material name="LightGrey">
        <color rgba="0.7 0.7 0.7 1.0"/>
      </material>
    </visual>
    <collision>
      <origin rpy="0 0 3.141592653589793" xyz="0 0 0"/>
      <geometry>
        <mesh filename="package://ur5_description/meshes/ur5/collision/shoulder.stl"/>
      </geometry>
    </collision>
    <inertial>
      <mass value="3.7"/>
      <origin rpy="0 0 0" xyz="0.0 0.0 0.0"/>
      <inertia ixx="0.014972352344389999" ixy="0.0" ixz="0.0" iyy="0.014972352344389999" iyz="0.0" izz="0.01040625"/>
    </inertial>
  </link>
  <joint name="robot_arm_shoulder_lift_joint" type="revolute">
    <parent link="robot_arm_shoulder_link"/>
    <child link="robot_arm_upper_arm_link"/>
    <origin rpy="1.569004245105693 0 -0.0001190217444835707" xyz="0.0002821443321676846 0 0"/>
    <axis xyz="0 0 1"/>
    <limit effort="150.0" lower="-3.141592653589793" upper="3.141592653589793" velocity="3.15"/>
    <dynamics damping="0.0" friction="0.0"/>
  </joint>
  <link name="robot_arm_upper_arm_link">
    <visual>
      <origin rpy="1.5707963267948966 0 -1.5707963267948966" xyz="0 0 0.136"/>
      <geometry>
        <mesh filename="package://ur5_description/meshes/ur5/visual/upperarm.dae"/>
      </geometry>
      <material name="LightGrey">
        <color rgba="0.7 0.7 0.7 1.0"/>
      </material>
    </visual>
    <collision>
      <origin rpy="1.5707963267948966 0 -1.5707963267948966" xyz="0 0 0.136"/>
      <geometry>
        <mesh filename="package://ur5_description/meshes/ur5/collision/upperarm.stl"/>
      </geometry>
    </collision>
    <inertial>
      <mass value="8.393"/>
      <origin rpy="0 1.5707963267948966 0" xyz="-0.2126299776780978 0.0 0.136"/>
      <inertia ixx="0.13404037360723267" ixy="0.0" ixz="0.0" iyy="0.13404037360723267" iyz="0.0" izz="0.0151074"/>
    </inertial>
  </link>
  <joint name="robot_arm_elbow_joint" type="revolute">
    <parent link="robot_arm_upper_arm_link"/>
    <child link="robot_arm_forearm_link"/>
    <origin rpy="0.001566108874752634 0.002815579965962084 4.479805951641281e-05" xyz="-0.4252599553561956 0 0"/>
    <axis xyz="0 0 1"/>
    <limit effort="150.0" lower="-3.141592653589793" upper="3.141592653589793" velocity="3.15"/>
    <dynamics damping="0.0" friction="0.0"/>
  </joint>
  <link name="robot_arm_forearm_link">
    <visual>
      <origin rpy="1.5707963267948966 0 -1.5707963267948966" xyz="0 0 0.0165"/>
      <geometry>
        <mesh filename="package://ur5_description/meshes/ur5/visual/forearm.dae"/>
      </geometry>
      <material name="LightGrey">
        <color rgba="0.7 0.7 0.7 1.0"/>
      </material>
    </visual>
    <collision>
      <origin rpy="1.5707963267948966 0 -1.5707963267948966" xyz="0 0 0.0165"/>
      <geometry>
        <mesh filename="package://ur5_description/meshes/ur5/collision/forearm.stl"/>
      </geometry>
    </collision>
    <inertial>
      <mass value="2.275"/>
      <origin rpy="0 1.5707963267948966 0" xyz="-0.2126299776780978 0.0 0.0165"/>
      <inertia ixx="0.031169742865989815" ixy="0.0" ixz="0.0" iyy="0.031169742865989815" iyz="0.0" izz="0.004095"/>
    </inertial>
  </link>
  <joint name="robot_arm_wrist_1_joint" type="revolute">
    <parent link="robot_arm_forearm_link"/>
    <child link="robot_arm_wrist_1_link"/>
    <origin rpy="3.138240306651916 -3.141057283537796 3.141498251723085" xyz="-0.3919335355218826 0.0003704732128467539 0.1105111827295567"/>
    <axis xyz="0 0 1"/>
    <limit effort="28.0" lower="-3.141592653589793" upper="3.141592653589793" velocity="3.2"/>
    <dynamics damping="0.0" friction="0.0"/>
  </joint>
  <link name="robot_arm_wrist_1_link">
    <visual>
      <origin rpy="1.5707963267948966 0 0" xyz="0 0 -0.093"/>
      <geometry>
        <mesh filename="package://ur5_description/meshes/ur5/visual/wrist1.dae"/>
      </geometry>
      <material name="LightGrey">
        <color rgba="0.7 0.7 0.7 1.0"/>
      </material>
    </visual>
    <collision>
      <origin rpy="1.5707963267948966 0 0" xyz="0 0 -0.093"/>
      <geometry>
        <mesh filename="package://ur5_description/meshes/ur5/collision/wrist1.stl"/>
      </geometry>
    </collision>
    <inertial>
      <mass value="1.219"/>
      <origin rpy="0 0 0" xyz="0.0 0.0 0.0"/>
      <inertia ixx="0.0026261090675042953" ixy="0.0" ixz="0.0" iyy="0.0026261090675042953" iyz="0.0" izz="0.0034284375"/>
    </inertial>
  </link>
  <joint name="robot_arm_wrist_2_joint" type="revolute">
    <parent link="robot_arm_wrist_1_link"/>
    <child link="robot_arm_wrist_2_link"/>
    <origin rpy="1.57217113608207 0 -7.678936993184548e-05" xyz="0.0001277755234390939 -0.09474587752911137 -0.0001302575944150798"/>
    <axis xyz="0 0 1"/>
    <limit effort="28.0" lower="-3.141592653589793" upper="3.141592653589793" velocity="3.2"/>
    <dynamics damping="0.0" friction="0.0"/>
  </joint>
  <link name="robot_arm_wrist_2_link">
    <visual>
      <origin rpy="0 0 0" xyz="0 0 -0.095"/>
      <geometry>
        <mesh filename="package://ur5_description/meshes/ur5/visual/wrist2.dae"/>
      </geometry>
      <material name="LightGrey">
        <color rgba="0.7 0.7 0.7 1.0"/>
      </material>
    </visual>
    <collision>
      <origin rpy="0 0 0" xyz="0 0 -0.095"/>
      <geometry>
        <mesh filename="package://ur5_description/meshes/ur5/collision/wrist2.stl"/>
      </geometry>
    </collision>
    <inertial>
      <mass value="1.219"/>
      <origin rpy="0 0 0" xyz="0.0 0.0 0.0"/>
      <inertia ixx="0.0017852868228412867" ixy="0.0" ixz="0.0" iyy="0.0017852868228412867" iyz="0.0" izz="0.0021942"/>
    </inertial>
  </link>
  <joint name="robot_arm_wrist_3_joint" type="revolute">
    <parent link="robot_arm_wrist_2_link"/>
    <child link="robot_arm_wrist_3_link"/>
    <origin rpy="1.571379818732016 3.141592653589793 3.141592325355712" xyz="0.0001750566616465034 0.0823080233035885 4.802607340829271e-05"/>
    <axis xyz="0 0 1"/>
    <limit effort="28.0" lower="-3.141592653589793" upper="3.141592653589793" velocity="3.2"/>
    <dynamics damping="0.0" friction="0.0"/>
  </joint>
  <link name="robot_arm_wrist_3_link">
    <visual>
      <origin rpy="1.5707963267948966 0 0" xyz="0 0 -0.0818"/>
      <geometry>
        <mesh filename="package://ur5_description/meshes/ur5/visual/wrist3.dae"/>
      </geometry>
      <material name="LightGrey">
        <color rgba="0.7 0.7 0.7 1.0"/>
      </material>
    </visual>
    <collision>
      <origin rpy="1.5707963267948966 0 0" xyz="0 0 -0.0823"/>
      <geometry>
        <mesh filename="package://ur5_description/meshes/ur5/collision/wrist3.stl"/>
      </geometry>
    </collision>
    <inertial>
      <mass value="0.1879"/>
      <origin rpy="0 0 0" xyz="0.0 0.0 -0.01525"/>
      <inertia ixx="8.062472608343e-05" ixy="0.0" ixz="0.0" iyy="8.062472608343e-05" iyz="0.0" izz="0.0001321171875"/>
    </inertial>
  </link>
  <joint name="robot_arm_ee_fixed_joint" type="fixed">
    <parent link="robot_arm_wrist_3_link"/>
    <child link="robot_arm_ee_link"/>
    <origin rpy="0.0 -1.5707963267948966 1.5707963267948966" xyz="0.0 0.0 0.0"/>
  </joint>
  <link name="robot_arm_ee_link">
    <collision>
      <geometry>
        <box size="0.01 0.01 0.01"/>
      </geometry>
      <origin rpy="0 0 0" xyz="-0.01 0 0"/>
    </collision>
  </link>
  <joint name="robot_arm_wrist_3_passive_joint" type="fixed">
    <origin rpy="0 0 0" xyz="0 0 0"/>
    <parent link="robot_arm_wrist_3_link"/>
    <child link="robot_arm_tool0"/>
  </joint>
  <transmission name="robot_arm_shoulder_pan_trans">
    <type>transmission_interface/SimpleTransmission</type>
    <joint name="robot_arm_shoulder_pan_joint">
      <hardwareInterface>hardware_interface/PositionJointInterface</hardwareInterface>
    </joint>
    <actuator name="robot_arm_shoulder_pan_motor">
      <mechanicalReduction>1</mechanicalReduction>
    </actuator>
  </transmission>
  <transmission name="robot_arm_shoulder_lift_trans">
    <type>transmission_interface/SimpleTransmission</type>
    <joint name="robot_arm_shoulder_lift_joint">
      <hardwareInterface>hardware_interface/PositionJointInterface</hardwareInterface>
    </joint>
    <actuator name="robot_arm_shoulder_lift_motor">
      <mechanicalReduction>1</mechanicalReduction>
    </actuator>
  </transmission>
  <transmission name="robot_arm_elbow_trans">
    <type>transmission_interface/SimpleTransmission</type>
    <joint name="robot_arm_elbow_joint">
      <hardwareInterface>hardware_interface/PositionJointInterface</hardwareInterface>
    </joint>
    <actuator name="robot_arm_elbow_motor">
      <mechanicalReduction>1</mechanicalReduction>
    </actuator>
  </transmission>
  <transmission name="robot_arm_wrist_1_trans">
    <type>transmission_interface/SimpleTransmission</type>
    <joint name="robot_arm_wrist_1_joint">
      <hardwareInterface>hardware_interface/PositionJointInterface</hardwareInterface>
    </joint>
    <actuator name="robot_arm_wrist_1_motor">
      <mechanicalReduction>1</mechanicalReduction>
    </actuator>
  </transmission>
  <transmission name="robot_arm_wrist_2_trans">
    <type>transmission_interface/SimpleTransmission</type>
    <joint name="robot_arm_wrist_2_joint">
      <hardwareInterface>hardware_interface/PositionJointInterface</hardwareInterface>
    </joint>
    <actuator name="robot_arm_wrist_2_motor">
      <mechanicalReduction>1</mechanicalReduction>
    </actuator>
  </transmission>
  <transmission name="robot_arm_wrist_3_trans">
    <type>transmission_interface/SimpleTransmission</type>
    <joint name="robot_arm_wrist_3_joint">
      <hardwareInterface>hardware_interface/PositionJointInterface</hardwareInterface>
    </joint>
    <actuator name="robot_arm_wrist_3_motor">
      <mechanicalReduction>1</mechanicalReduction>
    </actuator>
  </transmission>
  <gazebo reference="robot_arm_shoulder_link">
    <selfCollide>true</selfCollide>
  </gazebo>
  <gazebo reference="robot_arm_upper_arm_link">
    <selfCollide>true</selfCollide>
  </gazebo>
  <gazebo reference="robot_arm_forearm_link">
    <selfCollide>true</selfCollide>
  </gazebo>
  <gazebo reference="robot_arm_wrist_1_link">
    <selfCollide>true</selfCollide>
  </gazebo>
  <gazebo reference="robot_arm_wrist_3_link">
    <selfCollide>true</selfCollide>
  </gazebo>
  <gazebo reference="robot_arm_wrist_2_link">
    <selfCollide>true</selfCollide>
  </gazebo>
  <gazebo reference="robot_arm_ee_link">
    <selfCollide>true</selfCollide>
  </gazebo>
  <!-- ROS base_link to UR 'Base' Coordinates transform -->
  <link name="robot_arm_base"/>
  <joint name="robot_arm_base_link-base_fixed_joint" type="fixed">
    <!-- NOTE: this rotation is only needed as long as base_link itself is
                 not corrected wrt the real robot (ie: rotated over 180
                 degrees)
      -->
    <origin rpy="0 0 -3.141592653589793" xyz="0 0 0"/>
    <parent link="robot_arm_base_link"/>
    <child link="robot_arm_base"/>
  </joint>
  <!-- Frame coincident with all-zeros TCP on UR controller -->
  <link name="robot_arm_tool0"/>
  <joint name="robot_wsg50_support_joint" type="fixed">
    <!-- <xacro:insert_block name="origin"/> -->
    <origin rpy="0 0 3.1416" xyz="0.0 -0.01 0.005"/>
    <parent link="robot_wrist_rgbd_support_link"/>
    <child link="robot_wsg50_support_link"/>
  </joint>
  <link name="robot_wsg50_support_link">
    <inertial>
      <origin rpy="0 0 0" xyz="0 0 0.5"/>
      <mass value="1"/>
      <inertia ixx="100" ixy="0" ixz="0" iyy="100" iyz="0" izz="100"/>
    </inertial>
    <visual>
      <origin rpy="0 0 0" xyz="0 0 0"/>
      <geometry>
        <box size="0.05 0.125 0.01"/>
      </geometry>
      <material name="Black">
        <color rgba="0 0.0 0.0 1.0"/>
      </material>
    </visual>
    <collision>
      <origin rpy="0 0 0" xyz="0 0 0"/>
      <geometry>
        <box size="0.05 0.125 0.01"/>
      </geometry>
    </collision>
  </link>
  <gazebo reference="robot_wsg50_support_link">
    <material>Gazebo/Black</material>
    <gravity>true</gravity>
  </gazebo>
  <!-- <origin xyz="0.0 -0.01 0.007" rpy="0 0 0.0"/>
        </xacro:wsg50_support> -->
  <joint name="robot_wsg50_anterior_gripper_joint" type="fixed">
    <!-- <insert_block name="origin"/> -->
    <origin rpy="0 0 1.5707963267948966" xyz="0.0 0.01 0.005"/>
    <parent link="robot_wsg50_support_link"/>
    <child link="robot_wsg50_base_link"/>
  </joint>
  <!-- BASE LINK -->
  <link name="robot_wsg50_base_link">
    <inertial>
      <mass value="0.25"/>
      <origin xyz="0 0 0"/>
      <!--inertia ixx="1.0" ixy="0.0" ixz="0.0"
               iyy="100.0" iyz="0.0" 
               izz="1.0" /-->
      <inertia ixx="1.0" ixy="0.0" ixz="0.0" iyy="1.0" iyz="0.0" izz="1.0"/>
    </inertial>
    <visual>
      <origin rpy="0 0 0" xyz="0.0 0 0"/>
      <geometry>
        <mesh filename="package://ur5_description/meshes/wsg_50/WSG50_110.stl" scale="1 1 1"/>
        <!--box size="0.146 0.05 0.0735"/-->
      </geometry>
      <material name="grey">
        <color rgba="0.5 0.5 0.5 1"/>
      </material>
    </visual>
    <collision>
      <origin rpy="0 0 0" xyz="0.0 0 0"/>
      <geometry>
        <!--box size="0.146 0.05 0.0735"/-->
        <mesh filename="package://ur5_description/meshes/wsg_50/WSG50_110.stl" scale="1 1 1"/>
      </geometry>
    </collision>
  </link>
  <gazebo reference="robot_wsg50_base_link">
    <material>Gazebo/Grey</material>
    <turnGravityOff>false</turnGravityOff>
  </gazebo>
  <joint name="robot_wsg50_center_joint" type="fixed">
    <origin rpy="0 0 0" xyz="0 0 0.023"/>
    <!--origin xyz="-0.0067 0 0.049" rpy="0 0 0" /-->
    <parent link="robot_wsg50_base_link"/>
    <child link="robot_wsg50_center"/>
  </joint>
  <link name="robot_wsg50_center">
  </link>
  <!-- GRIPPER LEFT -->
  <joint name="robot_wsg50_finger_left_joint" type="prismatic">
    <limit effort="1.0" lower="-0.055" upper="-0.0027" velocity="1.0"/>
    <origin rpy="0 0 0" xyz="0 0 0"/>
    <!--origin xyz="-0.0067 0 0.049" rpy="0 0 0" /-->
    <parent link="robot_wsg50_base_link"/>
    <child link="robot_wsg50_gripper_left"/>
    <dynamics damping="100" friction="100"/>
    <axis xyz="1 0 0"/>
    <limit effort="100" velocity="100"/>
  </joint>
  <transmission name="robot_wsg50_base_trans_left">
    <type>pr2_mechanism_model/SimpleTransmission</type>
    <actuator name="robot_wsg50_base_motor_left">
      <mechanicalReduction>1</mechanicalReduction>
      <motorTorqueConstant>1</motorTorqueConstant>
    </actuator>
    <joint name="robot_wsg50_finger_left_joint">
      <hardwareInterface>hardware_interface/PositionJointInterface</hardwareInterface>
    </joint>
  </transmission>
  <link name="robot_wsg50_gripper_left">
    <inertial>
      <mass value="0.1"/>
      <origin xyz="0 0 0"/>
      <inertia ixx="1.0" ixy="0.0" ixz="0.0" iyy="1.0" iyz="0.0" izz="1.0"/>
    </inertial>
    <visual>
      <origin rpy="0 0 0" xyz="0.0 0 0"/>
      <geometry>
        <mesh filename="package://ur5_description/meshes/wsg_50/GUIDE_WSG50_110.dae" scale="0.001 0.001 0.001"/>
        <!--box size="0.0175 0.03 0.024"/-->
      </geometry>
      <material name="black">
        <color rgba="0 0 0 1"/>
      </material>
    </visual>
    <collision>
      <origin rpy="0 0 0" xyz="0 0 0"/>
      <geometry>
        <!--box size="0.0175 0.03 0.024"/-->
        <mesh filename="package://ur5_description/meshes/wsg_50/GUIDE_WSG50_110.dae" scale="0.001 0.001 0.001"/>
      </geometry>
    </collision>
    <contact_coefficients kd="1.0" kp="1000.0" mu="0"/>
  </link>
  <gazebo reference="robot_wsg50_gripper_left">
    <material>Gazebo/Blue</material>
    <turnGravityOff>false</turnGravityOff>
  </gazebo>
  <!-- LEFT FINGER -->
  <joint name="robot_wsg50_guide_joint_finger_left" type="fixed">
    <origin rpy="0 0 0" xyz="0 0 0.023"/>
    <parent link="robot_wsg50_gripper_left"/>
    <child link="robot_wsg50_finger_left"/>
    <dynamics damping="100" friction="100"/>
    <axis xyz="1 0 0"/>
    <limit effort="100" velocity="100"/>
  </joint>
  <link name="robot_wsg50_finger_left">
    <inertial>
      <mass value="0.1"/>
      <origin xyz="0 0 0"/>
      <inertia ixx="1.0" ixy="0.0" ixz="0.0" iyy="1.0" iyz="0.0" izz="1.0"/>
    </inertial>
    <visual>
      <origin rpy="0 0 0" xyz="0.0 0 0"/>
      <geometry>
        <mesh filename="package://ur5_description/meshes/wsg_50/WSG-FMF.dae" scale="0.001 0.001 0.001"/>
      </geometry>
      <material name="black">
        <color rgba="0 0 0 1"/>
      </material>
    </visual>
    <collision>
      <origin rpy="0 0 0" xyz="0 0 0"/>
      <geometry>
        <mesh filename="package://ur5_description/meshes/wsg_50/WSG-FMF.dae" scale="0.001 0.001 0.001"/>
      </geometry>
    </collision>
    <contact_coefficients kd="1.0" kp="1000.0" mu="0"/>
  </link>
  <gazebo reference="robot_wsg50_finger_left">
    <material>Gazebo/Blue</material>
    <turnGravityOff>false</turnGravityOff>
  </gazebo>
  <!-- GRIPPER RIGHT -->
  <joint name="robot_wsg50_finger_right_joint" type="prismatic">
    <limit effort="1.0" lower="0.0027" upper="0.055" velocity="1.0"/>
    <origin rpy="0 0 3.14159" xyz="0 0 0"/>
    <parent link="robot_wsg50_base_link"/>
    <child link="robot_wsg50_gripper_right"/>
    <axis xyz="-1 0 0"/>
    <dynamics damping="100" friction="100"/>
    <limit effort="100" velocity="100"/>
  </joint>
  <transmission name="robot_wsg50_base_trans_right">
    <type>pr2_mechanism_model/SimpleTransmission</type>
    <actuator name="robot_wsg50_base_motor_right">
      <mechanicalReduction>1</mechanicalReduction>
      <motorTorqueConstant>1</motorTorqueConstant>
    </actuator>
    <joint name="robot_wsg50_finger_right_joint">
      <hardwareInterface>hardware_interface/PositionJointInterface</hardwareInterface>
    </joint>
  </transmission>
  <link name="robot_wsg50_gripper_right">
    <inertial>
      <mass value="0.1"/>
      <origin xyz="0 0 0"/>
      <inertia ixx="1.0" ixy="0.0" ixz="0.0" iyy="1.0" iyz="0.0" izz="1.0"/>
    </inertial>
    <visual>
      <origin rpy="0 0 0" xyz="0.0 0 0"/>
      <geometry>
        <mesh filename="package://ur5_description/meshes/wsg_50/GUIDE_WSG50_110.dae" scale="0.001 0.001 0.001"/>
        <!--box size="0.0175 0.03 0.024"/-->
      </geometry>
      <material name="black">
        <color rgba="0 0 0 1"/>
      </material>
    </visual>
    <collision>
      <origin rpy="0 0 0" xyz="0 0 0"/>
      <geometry>
        <!--box size="0.0175 0.03 0.024"/-->
        <mesh filename="package://ur5_description/meshes/wsg_50/GUIDE_WSG50_110.dae" scale="0.001 0.001 0.001"/>
      </geometry>
    </collision>
    <contact_coefficients kd="1.0" kp="1000.0" mu="0"/>
  </link>
  <gazebo reference="gripper_right">
    <material>Gazebo/White</material>
    <turnGravityOff>false</turnGravityOff>
  </gazebo>
  <!-- RIGHT FINGER -->
  <joint name="robot_wsg50_guide_joint_finger_right" type="fixed">
    <origin rpy="0 0 0" xyz="0 0 0.023"/>
    <parent link="robot_wsg50_gripper_right"/>
    <child link="robot_wsg50_finger_right"/>
    <dynamics damping="100" friction="100"/>
    <axis xyz="1 0 0"/>
    <limit effort="100" velocity="100"/>
  </joint>
  <link name="robot_wsg50_finger_right">
    <inertial>
      <mass value="0.1"/>
      <origin xyz="0 0 0"/>
      <inertia ixx="1.0" ixy="0.0" ixz="0.0" iyy="1.0" iyz="0.0" izz="1.0"/>
    </inertial>
    <visual>
      <origin rpy="0 0 0" xyz="0.0 0 0"/>
      <geometry>
        <mesh filename="package://ur5_description/meshes/wsg_50/WSG-FMF.dae" scale="0.001 0.001 0.001"/>
      </geometry>
      <material name="black">
        <color rgba="0 0 0 1"/>
      </material>
    </visual>
    <collision>
      <origin rpy="0 0 0" xyz="0 0 0"/>
      <geometry>
        <mesh filename="package://ur5_description/meshes/wsg_50/WSG-FMF.dae" scale="0.001 0.001 0.001"/>
      </geometry>
    </collision>
    <contact_coefficients kd="1.0" kp="1000.0" mu="0"/>
  </link>
  <gazebo reference="robot_wsg50_finger_right">
    <material>Gazebo/White</material>
    <turnGravityOff>false</turnGravityOff>
  </gazebo>
  <!-- <origin xyz="0.0 0.01 0.005" rpy="0 0 ${pi/2}"/>
        </xacro:wsg_50_xacro> -->
  <joint name="robot_wrist_rgbd_support_joint" type="fixed">
    <!-- <xacro:insert_block name="origin"/> -->
    <origin rpy="0 0 0.0" xyz="0.0 0.0 0.00"/>
    <parent link="robot_arm_tool0"/>
    <child link="robot_wrist_rgbd_support_link"/>
  </joint>
  <link name="robot_wrist_rgbd_support_link">
    <inertial>
      <origin rpy="0 0 0" xyz="0 0 0.5"/>
      <mass value="1"/>
      <inertia ixx="100" ixy="0" ixz="0" iyy="100" iyz="0" izz="100"/>
    </inertial>
    <visual>
      <origin rpy="0 0 0" xyz="0.0105 0.0 0.001"/>
      <geometry>
        <box size="0.084 0.063 0.002"/>
      </geometry>
      <material name="Grey">
        <color rgba="0.7 0.7 0.7 1.0"/>
      </material>
    </visual>
    <collision>
      <origin rpy="0 0 0" xyz="0.0105 0.0 0.001"/>
      <geometry>
        <box size="0.084 0.063 0.002"/>
      </geometry>
    </collision>
  </link>
  <joint name="robot_wrist_rgbd_support_second_joint" type="fixed">
    <origin rpy="0 0.0 0.0" xyz="0.0515 0.0 0.001"/>
    <parent link="robot_wrist_rgbd_support_link"/>
    <child link="robot_wrist_rgbd_support_second_link"/>
  </joint>
  <link name="robot_wrist_rgbd_support_second_link">
    <inertial>
      <origin rpy="0 0 0" xyz="0 0 0.5"/>
      <mass value="1"/>
      <inertia ixx="100" ixy="0" ixz="0" iyy="100" iyz="0" izz="100"/>
    </inertial>
    <visual>
      <origin rpy="0.0 1.5707963267948966 0.0" xyz="0.0 0.0 0.019"/>
      <geometry>
        <box size="0.036 0.063 0.002"/>
      </geometry>
      <material name="Grey">
        <color rgba="0.7 0.7 0.7 1.0"/>
      </material>
    </visual>
    <collision>
      <origin rpy="0.0 1.5707963267948966 0.0" xyz="0.0 0.0 0.021"/>
      <geometry>
        <box size="0.04 0.063 0.002"/>
      </geometry>
    </collision>
  </link>
  <gazebo reference="robot_wrist_rgbd_support_link">
    <material>Gazebo/Black</material>
    <gravity>true</gravity>
  </gazebo>
  <!-- <origin xyz="0.0 0.0 0.00" rpy="0 0 0.0"/>
        </xacro:realsense_wrist_support> -->
  <!-- camera body, with origin at bottom screw mount -->
  <joint name="robot_realsense_camera_joint" type="fixed">
    <!-- <xacro:insert_block name="origin" /> -->
    <origin rpy="3.141592653589793 -1.5707963267948966 0" xyz="0.0515 0.0 0.065"/>
    <parent link="robot_arm_tool0"/>
    <child link="robot_realsense_camera_link"/>
  </joint>
  <link name="robot_realsense_camera_link">
    <visual>
      <!-- origin xyz="0 ${-r430_cam_mount_from_center_offset} ${r430_cam_height/2}" rpy="${M_PI/2} 0 ${M_PI/2}"/ -->
      <origin rpy="0 0 0" xyz="0 -0.0 0"/>
      <geometry>
        <!-- box size="${r430_cam_width} ${r430_cam_height} ${r430_cam_depth}"/ -->
        <mesh filename="package://ur5_description/meshes/sensors/intel_realsense_depth_camera_d435.dae"/>
      </geometry>
      <material name="aluminum">
        <color rgba="0.5 0.5 0.5 1"/>
      </material>
    </visual>
    <collision>
      <origin rpy="0 0 0" xyz="-0.0125 0.0 0.0"/>
      <geometry>
        <box size="0.025 0.1 0.025"/>
      </geometry>
    </collision>
    <inertial>
      <!-- The following are not reliable values, and should not be used for modeling -->
      <mass value="0.564"/>
      <origin xyz="0 0 0"/>
      <inertia ixx="0.003881243" ixy="0.0" ixz="0.0" iyy="0.000498940" iyz="0.0" izz="0.003879257"/>
    </inertial>
  </link>
  <!-- camera depth joints and links -->
  <joint name="robot_realsense_camera_depth_joint" type="fixed">
    <origin rpy="0 0 0" xyz="0.0 -0.0115 0.0"/>
    <parent link="robot_realsense_camera_link"/>
    <child link="robot_realsense_camera_depth_frame"/>
  </joint>
  <link name="robot_realsense_camera_depth_frame"/>
  <joint name="robot_realsense_camera_depth_optical_joint" type="fixed">
    <origin rpy="-1.5707963267948966 0 -1.5707963267948966" xyz="0 0 0"/>
    <parent link="robot_realsense_camera_depth_frame"/>
    <child link="robot_realsense_camera_depth_optical_frame"/>
  </joint>
  <link name="robot_realsense_camera_depth_optical_frame"/>
  <!-- camera left IR joints and links -->
  <joint name="robot_realsense_camera_left_ir_joint" type="fixed">
    <origin rpy="0 0 0" xyz="0 -0.021 0"/>
    <parent link="robot_realsense_camera_depth_frame"/>
    <child link="robot_realsense_camera_left_ir_frame"/>
  </joint>
  <link name="robot_realsense_camera_left_ir_frame"/>
  <joint name="robot_realsense_camera_left_ir_optical_joint" type="fixed">
    <origin rpy="-1.5707963267948966 0 -1.5707963267948966" xyz="0 0 0"/>
    <parent link="robot_realsense_camera_left_ir_frame"/>
    <child link="robot_realsense_camera_left_ir_optical_frame"/>
  </joint>
  <link name="robot_realsense_camera_left_ir_optical_frame"/>
  <!-- camera right IR joints and links -->
  <joint name="robot_realsense_camera_right_ir_joint" type="fixed">
    <origin rpy="0 0 0" xyz="0 0.029 0"/>
    <parent link="robot_realsense_camera_depth_frame"/>
    <child link="robot_realsense_camera_right_ir_frame"/>
  </joint>
  <link name="robot_realsense_camera_right_ir_frame"/>
  <joint name="robot_realsense_camera_right_ir_optical_joint" type="fixed">
    <origin rpy="-1.5707963267948966 0 -1.5707963267948966" xyz="0 0 0"/>
    <parent link="robot_realsense_camera_right_ir_frame"/>
    <child link="robot_realsense_camera_right_ir_optical_frame"/>
  </joint>
  <link name="robot_realsense_camera_right_ir_optical_frame"/>
  <!-- camera fisheye joints and links -->
  <joint name="robot_realsense_camera_fisheye_joint" type="fixed">
    <origin rpy="0 0 0" xyz="0 0.044 0"/>
    <parent link="robot_realsense_camera_depth_frame"/>
    <child link="robot_realsense_camera_fisheye_frame"/>
  </joint>
  <link name="robot_realsense_camera_fisheye_frame"/>
  <joint name="robot_realsense_camera_fisheye_optical_joint" type="fixed">
    <origin rpy="-1.5707963267948966 0 -1.5707963267948966" xyz="0 0 0"/>
    <parent link="robot_realsense_camera_fisheye_frame"/>
    <child link="robot_realsense_camera_fisheye_optical_frame"/>
  </joint>
  <link name="robot_realsense_camera_fisheye_optical_frame"/>
  <!-- RGBD sensor for simulation, same as Kinect -->
  <!-- <sensor_r430_gazebo/> -->
  <!-- <origin xyz="0.0515 0.0 0.065" rpy="${pi} ${-pi/2} 0"/>
        </xacro:sensor_r430> -->
</robot>
